2018-05-02 13:08:27,303 - root - ERROR - no existe el Alcalde en nuestra base de datos
Traceback (most recent call last):
  File "/home/rcancar/github/chatbot_v1/Salarios.py", line 33, in cargos
    return respuestas_bot(key,idioma)[1].format(cargo,int(nomina['salario']))
  File "/home/rcancar/anaconda3/lib/python3.6/site-packages/pymongo-3.6.0-py3.6-linux-x86_64.egg/pymongo/cursor.py", line 615, in __getitem__
    "instances" % index)
TypeError: index 'salario' cannot be applied to Cursor instances
2018-05-02 13:12:25,244 - root - ERROR - no existe el Alcalde en nuestra base de datos
Traceback (most recent call last):
  File "/home/rcancar/github/chatbot_v1/Salarios.py", line 33, in cargos
    return respuestas_bot(key,idioma)[1].format(cargo,int(nomina['salario']))
  File "/home/rcancar/anaconda3/lib/python3.6/site-packages/pymongo-3.6.0-py3.6-linux-x86_64.egg/pymongo/cursor.py", line 615, in __getitem__
    "instances" % index)
TypeError: index 'salario' cannot be applied to Cursor instances
2018-05-02 13:16:51,257 - telegram.ext.updater - ERROR - Error while getting Updates: Timed out
2018-05-02 13:16:51,258 - telegram.ext.dispatcher - ERROR - No error handlers are registered, logging exception...
Traceback (most recent call last):
  File "/home/rcancar/.local/lib/python3.6/site-packages/telegram/vendor/ptb_urllib3/urllib3/connectionpool.py", line 402, in _make_request
    six.raise_from(e, None)
  File "<string>", line 2, in raise_from
  File "/home/rcancar/.local/lib/python3.6/site-packages/telegram/vendor/ptb_urllib3/urllib3/connectionpool.py", line 398, in _make_request
    httplib_response = conn.getresponse()
  File "/home/rcancar/anaconda3/lib/python3.6/http/client.py", line 1331, in getresponse
    response.begin()
  File "/home/rcancar/anaconda3/lib/python3.6/http/client.py", line 297, in begin
    version, status, reason = self._read_status()
  File "/home/rcancar/anaconda3/lib/python3.6/http/client.py", line 258, in _read_status
    line = str(self.fp.readline(_MAXLINE + 1), "iso-8859-1")
  File "/home/rcancar/anaconda3/lib/python3.6/socket.py", line 586, in readinto
    return self._sock.recv_into(b)
  File "/home/rcancar/anaconda3/lib/python3.6/ssl.py", line 1009, in recv_into
    return self.read(nbytes, buffer)
  File "/home/rcancar/anaconda3/lib/python3.6/ssl.py", line 871, in read
    return self._sslobj.read(len, buffer)
  File "/home/rcancar/anaconda3/lib/python3.6/ssl.py", line 631, in read
    v = self._sslobj.read(len, buffer)
socket.timeout: The read operation timed out

During handling of the above exception, another exception occurred:

Traceback (most recent call last):
  File "/home/rcancar/.local/lib/python3.6/site-packages/telegram/utils/request.py", line 190, in _request_wrapper
    resp = self._con_pool.request(*args, **kwargs)
  File "/home/rcancar/.local/lib/python3.6/site-packages/telegram/vendor/ptb_urllib3/urllib3/request.py", line 70, in request
    **urlopen_kw)
  File "/home/rcancar/.local/lib/python3.6/site-packages/telegram/vendor/ptb_urllib3/urllib3/request.py", line 148, in request_encode_body
    return self.urlopen(method, url, **extra_kw)
  File "/home/rcancar/.local/lib/python3.6/site-packages/telegram/vendor/ptb_urllib3/urllib3/poolmanager.py", line 244, in urlopen
    response = conn.urlopen(method, u.request_uri, **kw)
  File "/home/rcancar/.local/lib/python3.6/site-packages/telegram/vendor/ptb_urllib3/urllib3/connectionpool.py", line 666, in urlopen
    _stacktrace=sys.exc_info()[2])
  File "/home/rcancar/.local/lib/python3.6/site-packages/telegram/vendor/ptb_urllib3/urllib3/util/retry.py", line 347, in increment
    raise six.reraise(type(error), error, _stacktrace)
  File "/home/rcancar/.local/lib/python3.6/site-packages/telegram/vendor/ptb_urllib3/urllib3/packages/six.py", line 686, in reraise
    raise value
  File "/home/rcancar/.local/lib/python3.6/site-packages/telegram/vendor/ptb_urllib3/urllib3/connectionpool.py", line 617, in urlopen
    chunked=chunked)
  File "/home/rcancar/.local/lib/python3.6/site-packages/telegram/vendor/ptb_urllib3/urllib3/connectionpool.py", line 405, in _make_request
    exc_cls=ReadTimeoutError)
  File "/home/rcancar/.local/lib/python3.6/site-packages/telegram/vendor/ptb_urllib3/urllib3/connectionpool.py", line 321, in _raise_timeout
    raise exc_cls(*args)
telegram.vendor.ptb_urllib3.urllib3.exceptions.ReadTimeoutError: HTTPSConnectionPool(host='api.telegram.org', port=443): Read timed out. (read timeout=12.0)

During handling of the above exception, another exception occurred:

Traceback (most recent call last):
  File "/home/rcancar/.local/lib/python3.6/site-packages/telegram/ext/updater.py", line 286, in _start_polling
    allowed_updates=allowed_updates)
  File "/home/rcancar/.local/lib/python3.6/site-packages/telegram/bot.py", line 60, in decorator
    result = func(self, *args, **kwargs)
  File "/home/rcancar/.local/lib/python3.6/site-packages/telegram/bot.py", line 1720, in get_updates
    result = self._request.post(url, data, timeout=float(read_latency) + float(timeout))
  File "/home/rcancar/.local/lib/python3.6/site-packages/telegram/utils/request.py", line 272, in post
    **urlopen_kwargs)
  File "/home/rcancar/.local/lib/python3.6/site-packages/telegram/utils/request.py", line 192, in _request_wrapper
    raise TimedOut()
telegram.error.TimedOut: Timed out
2018-05-02 13:49:24,375 - telegram.ext.updater - ERROR - Error while getting Updates: Timed out
2018-05-02 15:02:55,219 - telegram.ext.updater - ERROR - Error while getting Updates: Timed out
